2022-12-05 13:05:26,827 INFO Start : Creation du KafkaProducer with all brokers 
2022-12-05 13:05:28,845 INFO  Begin: Call Email Sender Alert ....************************************
2022-12-05 13:05:29,075 INFO OK: Send email ...
2022-12-05 13:05:29,076 ERROR Kafka Exception sending message to Kafka/Kafkaproducer name 'KafkaTimeoutError' is not defined
Traceback (most recent call last):
  File "kafkabrokermonitor.py", line 54, in callkafkaproducer
    producer = KafkaProducer(bootstrap_servers=['10.10.140.110:9093','10.10.140.111:9093','10.10.140.112:9093'],value_serializer=lambda v: json.dumps(v).encode('utf-8'))
  File "C:\Users\SOULEYSANOGO\AppData\Local\Programs\Python\Python38-32\lib\site-packages\kafka\producer\kafka.py", line 381, in __init__
    client = KafkaClient(metrics=self._metrics, metric_group_prefix='producer',
  File "C:\Users\SOULEYSANOGO\AppData\Local\Programs\Python\Python38-32\lib\site-packages\kafka\client_async.py", line 244, in __init__
    self.config['api_version'] = self.check_version(timeout=check_timeout)
  File "C:\Users\SOULEYSANOGO\AppData\Local\Programs\Python\Python38-32\lib\site-packages\kafka\client_async.py", line 927, in check_version
    raise Errors.NoBrokersAvailable()
kafka.errors.NoBrokersAvailable: NoBrokersAvailable

During handling of the above exception, another exception occurred:

Traceback (most recent call last):
  File "kafkabrokermonitor.py", line 172, in doTaskKafka
    callkafkaproducer()
  File "kafkabrokermonitor.py", line 64, in callkafkaproducer
    except KafkaTimeoutError as kte:
NameError: name 'KafkaTimeoutError' is not defined
2022-12-05 13:06:29,111 INFO Start : Creation du KafkaProducer with all brokers 
2022-12-05 13:06:31,122 INFO  Begin: Call Email Sender Alert ....************************************
2022-12-05 13:06:31,283 INFO OK: Send email ...
2022-12-05 13:06:31,285 ERROR Kafka Exception sending message to Kafka/Kafkaproducer name 'KafkaTimeoutError' is not defined
Traceback (most recent call last):
  File "kafkabrokermonitor.py", line 54, in callkafkaproducer
    producer = KafkaProducer(bootstrap_servers=['10.10.140.110:9093','10.10.140.111:9093','10.10.140.112:9093'],value_serializer=lambda v: json.dumps(v).encode('utf-8'))
  File "C:\Users\SOULEYSANOGO\AppData\Local\Programs\Python\Python38-32\lib\site-packages\kafka\producer\kafka.py", line 381, in __init__
    client = KafkaClient(metrics=self._metrics, metric_group_prefix='producer',
  File "C:\Users\SOULEYSANOGO\AppData\Local\Programs\Python\Python38-32\lib\site-packages\kafka\client_async.py", line 244, in __init__
    self.config['api_version'] = self.check_version(timeout=check_timeout)
  File "C:\Users\SOULEYSANOGO\AppData\Local\Programs\Python\Python38-32\lib\site-packages\kafka\client_async.py", line 927, in check_version
    raise Errors.NoBrokersAvailable()
kafka.errors.NoBrokersAvailable: NoBrokersAvailable

During handling of the above exception, another exception occurred:

Traceback (most recent call last):
  File "kafkabrokermonitor.py", line 172, in doTaskKafka
    callkafkaproducer()
  File "kafkabrokermonitor.py", line 64, in callkafkaproducer
    except KafkaTimeoutError as kte:
NameError: name 'KafkaTimeoutError' is not defined
2022-12-05 13:07:31,320 INFO Start : Creation du KafkaProducer with all brokers 
2022-12-05 13:07:33,329 INFO  Begin: Call Email Sender Alert ....************************************
2022-12-05 13:07:33,481 INFO OK: Send email ...
2022-12-05 13:07:33,482 ERROR Kafka Exception sending message to Kafka/Kafkaproducer name 'KafkaTimeoutError' is not defined
Traceback (most recent call last):
  File "kafkabrokermonitor.py", line 54, in callkafkaproducer
    producer = KafkaProducer(bootstrap_servers=['10.10.140.110:9093','10.10.140.111:9093','10.10.140.112:9093'],value_serializer=lambda v: json.dumps(v).encode('utf-8'))
  File "C:\Users\SOULEYSANOGO\AppData\Local\Programs\Python\Python38-32\lib\site-packages\kafka\producer\kafka.py", line 381, in __init__
    client = KafkaClient(metrics=self._metrics, metric_group_prefix='producer',
  File "C:\Users\SOULEYSANOGO\AppData\Local\Programs\Python\Python38-32\lib\site-packages\kafka\client_async.py", line 244, in __init__
    self.config['api_version'] = self.check_version(timeout=check_timeout)
  File "C:\Users\SOULEYSANOGO\AppData\Local\Programs\Python\Python38-32\lib\site-packages\kafka\client_async.py", line 927, in check_version
    raise Errors.NoBrokersAvailable()
kafka.errors.NoBrokersAvailable: NoBrokersAvailable

During handling of the above exception, another exception occurred:

Traceback (most recent call last):
  File "kafkabrokermonitor.py", line 172, in doTaskKafka
    callkafkaproducer()
  File "kafkabrokermonitor.py", line 64, in callkafkaproducer
    except KafkaTimeoutError as kte:
NameError: name 'KafkaTimeoutError' is not defined
2022-12-05 13:08:33,515 INFO Start : Creation du KafkaProducer with all brokers 
2022-12-05 13:08:35,524 INFO  Begin: Call Email Sender Alert ....************************************
2022-12-05 13:08:35,671 INFO OK: Send email ...
2022-12-05 13:08:35,674 ERROR Kafka Exception sending message to Kafka/Kafkaproducer name 'KafkaTimeoutError' is not defined
Traceback (most recent call last):
  File "kafkabrokermonitor.py", line 54, in callkafkaproducer
    producer = KafkaProducer(bootstrap_servers=['10.10.140.110:9093','10.10.140.111:9093','10.10.140.112:9093'],value_serializer=lambda v: json.dumps(v).encode('utf-8'))
  File "C:\Users\SOULEYSANOGO\AppData\Local\Programs\Python\Python38-32\lib\site-packages\kafka\producer\kafka.py", line 381, in __init__
    client = KafkaClient(metrics=self._metrics, metric_group_prefix='producer',
  File "C:\Users\SOULEYSANOGO\AppData\Local\Programs\Python\Python38-32\lib\site-packages\kafka\client_async.py", line 244, in __init__
    self.config['api_version'] = self.check_version(timeout=check_timeout)
  File "C:\Users\SOULEYSANOGO\AppData\Local\Programs\Python\Python38-32\lib\site-packages\kafka\client_async.py", line 927, in check_version
    raise Errors.NoBrokersAvailable()
kafka.errors.NoBrokersAvailable: NoBrokersAvailable

During handling of the above exception, another exception occurred:

Traceback (most recent call last):
  File "kafkabrokermonitor.py", line 172, in doTaskKafka
    callkafkaproducer()
  File "kafkabrokermonitor.py", line 64, in callkafkaproducer
    except KafkaTimeoutError as kte:
NameError: name 'KafkaTimeoutError' is not defined
