2022-12-04 10:35:12,877 INFO Start : Creation du KafkaProducer with all brokers 
2022-12-04 10:37:12,885 INFO RAS : Test du Broker Kafka OK ....
2022-12-04 10:37:12,885 ERROR Kafka Exception sending message to Kafka/Kafkaproducer name 'KafkaTimeoutError' is not defined
Traceback (most recent call last):
  File "kafkabrokermonitor.py", line 60, in callkafkaproducer
    producer.send(topic='supervisionmonitoring',key= b'MTN', value={'refContrat': '255358642'})
  File "C:\Users\SOULEYSANOGO\AppData\Local\Programs\Python\Python37\lib\site-packages\kafka\producer\kafka.py", line 576, in send
    self._wait_on_metadata(topic, self.config['max_block_ms'] / 1000.0)
  File "C:\Users\SOULEYSANOGO\AppData\Local\Programs\Python\Python37\lib\site-packages\kafka\producer\kafka.py", line 703, in _wait_on_metadata
    "Failed to update metadata after %.1f secs." % (max_wait,))
kafka.errors.KafkaTimeoutError: KafkaTimeoutError: Failed to update metadata after 120.0 secs.

During handling of the above exception, another exception occurred:

Traceback (most recent call last):
  File "kafkabrokermonitor.py", line 165, in doTaskKafka
    callkafkaproducer()
  File "kafkabrokermonitor.py", line 67, in callkafkaproducer
    except KafkaTimeoutError as kte:
NameError: name 'KafkaTimeoutError' is not defined
2022-12-04 10:38:13,359 INFO Start : Creation du KafkaProducer with all brokers 
2022-12-04 10:40:13,364 INFO RAS : Test du Broker Kafka OK ....
2022-12-04 10:40:13,364 ERROR Kafka Exception sending message to Kafka/Kafkaproducer name 'KafkaTimeoutError' is not defined
Traceback (most recent call last):
  File "kafkabrokermonitor.py", line 60, in callkafkaproducer
    producer.send(topic='supervisionmonitoring',key= b'MTN', value={'refContrat': '255358642'})
  File "C:\Users\SOULEYSANOGO\AppData\Local\Programs\Python\Python37\lib\site-packages\kafka\producer\kafka.py", line 576, in send
    self._wait_on_metadata(topic, self.config['max_block_ms'] / 1000.0)
  File "C:\Users\SOULEYSANOGO\AppData\Local\Programs\Python\Python37\lib\site-packages\kafka\producer\kafka.py", line 703, in _wait_on_metadata
    "Failed to update metadata after %.1f secs." % (max_wait,))
kafka.errors.KafkaTimeoutError: KafkaTimeoutError: Failed to update metadata after 120.0 secs.

During handling of the above exception, another exception occurred:

Traceback (most recent call last):
  File "kafkabrokermonitor.py", line 165, in doTaskKafka
    callkafkaproducer()
  File "kafkabrokermonitor.py", line 67, in callkafkaproducer
    except KafkaTimeoutError as kte:
NameError: name 'KafkaTimeoutError' is not defined
2022-12-04 10:41:13,886 INFO Start : Creation du KafkaProducer with all brokers 
2022-12-04 10:43:13,896 INFO RAS : Test du Broker Kafka OK ....
2022-12-04 10:43:13,896 ERROR Kafka Exception sending message to Kafka/Kafkaproducer name 'KafkaTimeoutError' is not defined
Traceback (most recent call last):
  File "kafkabrokermonitor.py", line 60, in callkafkaproducer
    producer.send(topic='supervisionmonitoring',key= b'MTN', value={'refContrat': '255358642'})
  File "C:\Users\SOULEYSANOGO\AppData\Local\Programs\Python\Python37\lib\site-packages\kafka\producer\kafka.py", line 576, in send
    self._wait_on_metadata(topic, self.config['max_block_ms'] / 1000.0)
  File "C:\Users\SOULEYSANOGO\AppData\Local\Programs\Python\Python37\lib\site-packages\kafka\producer\kafka.py", line 703, in _wait_on_metadata
    "Failed to update metadata after %.1f secs." % (max_wait,))
kafka.errors.KafkaTimeoutError: KafkaTimeoutError: Failed to update metadata after 120.0 secs.

During handling of the above exception, another exception occurred:

Traceback (most recent call last):
  File "kafkabrokermonitor.py", line 165, in doTaskKafka
    callkafkaproducer()
  File "kafkabrokermonitor.py", line 67, in callkafkaproducer
    except KafkaTimeoutError as kte:
NameError: name 'KafkaTimeoutError' is not defined
2022-12-04 10:44:14,413 INFO Start : Creation du KafkaProducer with all brokers 
2022-12-04 10:46:14,426 INFO RAS : Test du Broker Kafka OK ....
2022-12-04 10:46:14,427 ERROR Kafka Exception sending message to Kafka/Kafkaproducer name 'KafkaTimeoutError' is not defined
Traceback (most recent call last):
  File "kafkabrokermonitor.py", line 60, in callkafkaproducer
    producer.send(topic='supervisionmonitoring',key= b'MTN', value={'refContrat': '255358642'})
  File "C:\Users\SOULEYSANOGO\AppData\Local\Programs\Python\Python37\lib\site-packages\kafka\producer\kafka.py", line 576, in send
    self._wait_on_metadata(topic, self.config['max_block_ms'] / 1000.0)
  File "C:\Users\SOULEYSANOGO\AppData\Local\Programs\Python\Python37\lib\site-packages\kafka\producer\kafka.py", line 703, in _wait_on_metadata
    "Failed to update metadata after %.1f secs." % (max_wait,))
kafka.errors.KafkaTimeoutError: KafkaTimeoutError: Failed to update metadata after 120.0 secs.

During handling of the above exception, another exception occurred:

Traceback (most recent call last):
  File "kafkabrokermonitor.py", line 165, in doTaskKafka
    callkafkaproducer()
  File "kafkabrokermonitor.py", line 67, in callkafkaproducer
    except KafkaTimeoutError as kte:
NameError: name 'KafkaTimeoutError' is not defined
